Workbook

Sheet Start Here
B2: FLUENCY LAB — Fluency Tracker & Dashboard
B3: Module 1: Multi-Digit Addition & Subtraction · Grade 8 Mathematics
B5: What this workbook does
B6: It turns the scores from your weekly fluency checks into (1) an at-a-glance mastery dashboard that colors itself, (2) a growth trend for every student, and (3) a pre/post effect-size analysis that shows whether the program is working.
B8: The four tabs
B9: • Roster — your 61 students, pre-loaded, with baseline IXL levels and a starting intervention group (Red / Yellow / Green).
B10: • Mastery Dashboard — type each student's weekly mastery % (0–100). Cells band themselves; Latest, Slope, and Status update automatically.
B11: • Pre–Post Analysis — type each student's pre-test and post-test %. Cohen's d and the paired t-test compute automatically.
B13: How to read it
B14: Mastery bands: ≥ 80 = On track (green) 60–79 = Developing (yellow) below 60 = Intervention (red)
B15: Slope = average change in mastery per check. A positive slope means the student is climbing; zero or negative is a flag.
B16: Cohen's d = the size of the pre→post gain. As a rule of thumb (Hattie): 0.2 small · 0.5 medium · 0.8 large. Roughly 0.4 is a typical year's growth, so a module clearing 0.4 is doing real work.
... B21: To use in Google Sheets: upload this file to Google Drive and open it with Google Sheets (File ▸ Import, or just double-click). All formulas, colors, and the chart carry over.

Sheet Roster
A1: # | B1: Student | C1: Baseline IXL Level | D1: Baseline Gap (grade) | E1: Sample Recommended Skill | F1: Starting Group
A2: 1 | B2: Wells Allen | C2: 350 | D2: Third grade | E2: Find the area of complex figures by dividi | F2: Yellow
A3: 2 | B3: Guinevere Arena | C3: 210 | D3: First grade | E3: Cubes and rectangular prisms | F3: Red
A4: 3 | B4: Hayden Banks | C4: 470 | D4: Fourth grade | E4: Use fractions to find the measure of an an | F4: Green
A5: 4 | B5: Maggie Rae Bricker | C5: 230 | D5: Second grade | E5: Tile a rectangle with squares | F5: Red
A6: 5 | B6: Shaan Carlson | C6: 430 | D6: Third grade | E6: Find the area of complex figures by dividi | F6: Yellow
A7: 6 | B7: Giovanna Castaneda | C7: 410 | D7: Third grade | E7: Find the area of complex figures by dividi | F7: Yellow
A8: 7 | B8: Caleigh Castelin | C8: 380 | D8: Third grade | E8: Find the area of rectangles: word problems | F8: Yellow
A9: 8 | B9: Sadie Castelin | C9: 590 | D9: Seventh grade | E9: Cross sections of three-dimensional figure | F9: Green
A10: 9 | B10: Julie Cola | C10: 570 | D10: Sixth grade | E10: Understanding area of a parallelogram | F10: Green
A11: 10 | B11: Cramer Dean | C11: 0 | D11: Sixth grade | E11: Volume of cubes and rectangular prisms wit | F11: Red
A12: 11 | B12: Fredrick Eifler | C12: 550 | D12: Fifth grade | E12: Volume of cubes and rectangular prisms | F12: Green
A13: 12 | B13: Anya Galvez | C13: 390 | D13: Third grade | E13: Perimeter of rectangles | F13: Yellow
... A32: 31 | B32: Logan Wright | C32: 280 | D32: Third grade | E32: Identify parallelograms | F32: Red
A33: 32 | B33: Harlan Butler
A34: 33 | B34: Emma Canterbury
A35: 34 | B35: Aubriella Covington
A36: 35 | B36: Charity Davis
A37: 36 | B37: Milo Davis
A38: 37 | B38: Price Edmonds
A39: 38 | B39: Andres Falcon
A40: 39 | B40: Malachi Gann
A41: 40 | B41: Roan Gardner
A42: 41 | B42: Ava Grucci
A43: 42 | B43: Emma Holton
A44: 43 | B44: James Kelly | C44: 0 | D44: Fifth grade | E44: Volume of rectangular prisms made of unit | F44: Red
A45: 44 | B45: Henry Kesler | C45: 790 | D45: Seventh grade | E45: Triangle inequality | F45: Green
A46: 45 | B46: Hannah Kirschner
A47: 46 | B47: Phoenix Lamore
A48: 47 | B48: Makayla Lewis
A49: 48 | B49: Aria Meduri | C49: 450 | D49: Fourth grade | E49: Sides and angles of quadrilaterals | F49: Yellow
A50: 49 | B50: Jaysen Murdaugh | C50: 0 | D50: Fifth grade | E50: Volume of rectangular prisms made of unit | F50: Red
A51: 50 | B51: Jackson Penland | C51: 510 | D51: Fourth grade | E51: Acute, right, obtuse, and straight angles | F51: Green
A52: 51 | B52: Austin Penley
A53: 52 | B53: Leila Scroggs | C53: 680 | D53: Seventh grade | E53: Area of compound figures with triangles, s | F53: Green
A54: 53 | B54: Clara Shaw
A55: 54 | B55: Kaitlyn Shifflett | C55: 540 | D55: Fourth grade | E55: Sides and angles of quadrilaterals | F55: Green
A56: 55 | B56: Hazel Smith
A57: 56 | B57: John Stalowy
A58: 57 | B58: Brigitte Trautman
...

Sheet Mastery Dashboard
A1: Mastery Dashboard — weekly fluency checks
A2: Type each student's mastery % (0–100) in the shaded Check columns. Everything else updates itself.
A3: Student | B3: Group | C3: Check 1 | D3: Check 2 | E3: Check 3 | F3: Check 4 | G3: Check 5 | H3: Check 6 | I3: Check 7 | J3: Check 8 | K3: Check 9 | L3: Check 10 | M3: Latest | N3: Slope | O3: Status
B4: Week # | C4: 1 | D4: 2 | E4: 3 | F4: 4 | G4: 5 | H4: 6 | I4: 7 | J4: 8 | K4: 9 | L4: 10
A5: Wells Allen | B5: =IFERROR(INDEX(Roster!$F$2:$F$62,MATCH(A5,Roster!$B$2:$B$62,0))&"","") -> Yellow | M5: =IFERROR(LOOKUP(9.99E+307,C5:L5),"") | N5: =IFERROR(ROUND(SLOPE(C5:L5,$C$4:$L$4),1),"") | O5: =IF(M5="","",IF(M5>=80,"On track",IF(M5>=60,"Developing","Intervention")))
A6: Guinevere Arena | B6: =IFERROR(INDEX(Roster!$F$2:$F$62,MATCH(A6,Roster!$B$2:$B$62,0))&"","") -> Red | M6: =IFERROR(LOOKUP(9.99E+307,C6:L6),"") | N6: =IFERROR(ROUND(SLOPE(C6:L6,$C$4:$L$4),1),"") | O6: =IF(M6="","",IF(M6>=80,"On track",IF(M6>=60,"Developing","Intervention")))
A7: Hayden Banks | B7: =IFERROR(INDEX(Roster!$F$2:$F$62,MATCH(A7,Roster!$B$2:$B$62,0))&"","") -> Green | M7: =IFERROR(LOOKUP(9.99E+307,C7:L7),"") | N7: =IFERROR(ROUND(SLOPE(C7:L7,$C$4:$L$4),1),"") | O7: =IF(M7="","",IF(M7>=80,"On track",IF(M7>=60,"Developing","Intervention")))
A8: Maggie Rae Bricker | B8: =IFERROR(INDEX(Roster!$F$2:$F$62,MATCH(A8,Roster!$B$2:$B$62,0))&"","") -> Red | M8: =IFERROR(LOOKUP(9.99E+307,C8:L8),"") | N8: =IFERROR(ROUND(SLOPE(C8:L8,$C$4:$L$4),1),"") | O8: =IF(M8="","",IF(M8>=80,"On track",IF(M8>=60,"Developing","Intervention")))
A9: Shaan Carlson | B9: =IFERROR(INDEX(Roster!$F$2:$F$62,MATCH(A9,Roster!$B$2:$B$62,0))&"","") -> Yellow | M9: =IFERROR(LOOKUP(9.99E+307,C9:L9),"") | N9: =IFERROR(ROUND(SLOPE(C9:L9,$C$4:$L$4),1),"") | O9: =IF(M9="","",IF(M9>=80,"On track",IF(M9>=60,"Developing","Intervention")))
A10: Giovanna Castaneda | B10: =IFERROR(INDEX(Roster!$F$2:$F$62,MATCH(A10,Roster!$B$2:$B$62,0))&"","") -> Yellow | M10: =IFERROR(LOOKUP(9.99E+307,C10:L10),"") | N10: =IFERROR(ROUND(SLOPE(C10:L10,$C$4:$L$4),1),"") | O10: =IF(M10="","",IF(M10>=80,"On track",IF(M10>=60,"Developing","Intervention")))
A11: Caleigh Castelin | B11: =IFERROR(INDEX(Roster!$F$2:$F$62,MATCH(A11,Roster!$B$2:$B$62,0))&"","") -> Yellow | M11: =IFERROR(LOOKUP(9.99E+307,C11:L11),"") | N11: =IFERROR(ROUND(SLOPE(C11:L11,$C$4:$L$4),1),"") | O11: =IF(M11="","",IF(M11>=80,"On track",IF(M11>=60,"Developing","Intervention")))
A12: Sadie Castelin | B12: =IFERROR(INDEX(Roster!$F$2:$F$62,MATCH(A12,Roster!$B$2:$B$62,0))&"","") -> Green | M12: =IFERROR(LOOKUP(9.99E+307,C12:L12),"") | N12: =IFERROR(ROUND(SLOPE(C12:L12,$C$4:$L$4),1),"") | O12: =IF(M12="","",IF(M12>=80,"On track",IF(M12>=60,"Developing","Intervention")))
A13: Julie Cola | B13: =IFERROR(INDEX(Roster!$F$2:$F$62,MATCH(A13,Roster!$B$2:$B$62,0))&"","") -> Green | M13: =IFERROR(LOOKUP(9.99E+307,C13:L13),"") | N13: =IFERROR(ROUND(SLOPE(C13:L13,$C$4:$L$4),1),"") | O13: =IF(M13="","",IF(M13>=80,"On track",IF(M13>=60,"Developing","Intervention")))
A14: Cramer Dean | B14: =IFERROR(INDEX(Roster!$F$2:$F$62,MATCH(A14,Roster!$B$2:$B$62,0))&"","") -> Red | M14: =IFERROR(LOOKUP(9.99E+307,C14:L14),"") | N14: =IFERROR(ROUND(SLOPE(C14:L14,$C$4:$L$4),1),"") | O14: =IF(M14="","",IF(M14>=80,"On track",IF(M14>=60,"Developing","Intervention")))
A15: Fredrick Eifler | B15: =IFERROR(INDEX(Roster!$F$2:$F$62,MATCH(A15,Roster!$B$2:$B$62,0))&"","") -> Green | M15: =IFERROR(LOOKUP(9.99E+307,C15:L15),"") | N15: =IFERROR(ROUND(SLOPE(C15:L15,$C$4:$L$4),1),"") | O15: =IF(M15="","",IF(M15>=80,"On track",IF(M15>=60,"Developing","Intervention")))
A16: Anya Galvez | B16: =IFERROR(INDEX(Roster!$F$2:$F$62,MATCH(A16,Roster!$B$2:$B$62,0))&"","") -> Yellow | M16: =IFERROR(LOOKUP(9.99E+307,C16:L16),"") | N16: =IFERROR(ROUND(SLOPE(C16:L16,$C$4:$L$4),1),"") | O16: =IF(M16="","",IF(M16>=80,"On track",IF(M16>=60,"Developing","Intervention")))
... A65: Aubree Younglove | B65: =IFERROR(INDEX(Roster!$F$2:$F$62,MATCH(A65,Roster!$B$2:$B$62,0))&"","") | M65: =IFERROR(LOOKUP(9.99E+307,C65:L65),"") | N65: =IFERROR(ROUND(SLOPE(C65:L65,$C$4:$L$4),1),"") | O65: =IF(M65="","",IF(M65>=80,"On track",IF(M65>=60,"Developing","Intervention")))
A66: Class average | C66: =IFERROR(ROUND(AVERAGE(C5:C65),0),"") | D66: =IFERROR(ROUND(AVERAGE(D5:D65),0),"") | E66: =IFERROR(ROUND(AVERAGE(E5:E65),0),"") | F66: =IFERROR(ROUND(AVERAGE(F5:F65),0),"") | G66: =IFERROR(ROUND(AVERAGE(G5:G65),0),"") | H66: =IFERROR(ROUND(AVERAGE(H5:H65),0),"") | I66: =IFERROR(ROUND(AVERAGE(I5:I65),0),"") | J66: =IFERROR(ROUND(AVERAGE(J5:J65),0),"") | ... L66: =IFERROR(ROUND(AVERAGE(L5:L65),0),"")

Sheet Pre-Post Analysis
A1: Pre / Post Analysis — module impact
A2: Type each student's pre-test and post-test mastery % (0–100). Fill both for a student to count in the analysis.
A3: Student | B3: Pre % | C3: Post % | D3: Gain | F3: Summary
A4: Wells Allen | D4: =IF(OR(B4="",C4=""),"",C4-B4) | F4: Students with both scores (n) | G4: =COUNT(D4:D64) -> 0
A5: Guinevere Arena | D5: =IF(OR(B5="",C5=""),"",C5-B5) | F5: Mean pre % | G5: =IFERROR(AVERAGE(B4:B64),"")
A6: Hayden Banks | D6: =IF(OR(B6="",C6=""),"",C6-B6) | F6: Mean post % | G6: =IFERROR(AVERAGE(C4:C64),"")
A7: Maggie Rae Bricker | D7: =IF(OR(B7="",C7=""),"",C7-B7) | F7: Mean gain (pts) | G7: =IFERROR(AVERAGE(D4:D64),"")
A8: Shaan Carlson | D8: =IF(OR(B8="",C8=""),"",C8-B8) | F8: SD pre | G8: =IFERROR(STDEV(B4:B64),"")
A9: Giovanna Castaneda | D9: =IF(OR(B9="",C9=""),"",C9-B9) | F9: SD post | G9: =IFERROR(STDEV(C4:C64),"")
A10: Caleigh Castelin | D10: =IF(OR(B10="",C10=""),"",C10-B10) | F10: Pooled SD | G10: =IFERROR(SQRT((STDEV(B4:B64)^2+STDEV(C4:C64)^2)/2),"")
A11: Sadie Castelin | D11: =IF(OR(B11="",C11=""),"",C11-B11) | F11: Cohen's d (effect size) | G11: =IFERROR((AVERAGE(C4:C64)-AVERAGE(B4:B64))/SQRT((STDEV(B4:B64)^2+STDEV(C4:C64)^2)/2),"")
A12: Julie Cola | D12: =IF(OR(B12="",C12=""),"",C12-B12) | F12: Paired t-test p-value | G12: =IFERROR(TTEST(B4:B64,C4:C64,2,1),"")
A13: Cramer Dean | D13: =IF(OR(B13="",C13=""),"",C13-B13) | F13: Interpretation (Hattie) | G13: =IFERROR(IF(G11="","",IF(G11>=0.8,"Large effect",IF(G11>=0.5,"Medium effect",IF(G11>=0.4,"~A year's growth",IF(G11>=0.2,"Small effect","Negligible"))))),"")
A14: Fredrick Eifler | D14: =IF(OR(B14="",C14=""),"",C14-B14)
A15: Anya Galvez | D15: =IF(OR(B15="",C15=""),"",C15-B15) | F15: d = (mean post − mean pre) ÷ pooled SD. p from a two-tailed paired t-test.
A16: Katelyn Good | D16: =IF(OR(B16="",C16=""),"",C16-B16)
A17: Micah Hernandez | D17: =IF(OR(B17="",C17=""),"",C17-B17)
A18: Megan Herrera-Mondragon | D18: =IF(OR(B18="",C18=""),"",C18-B18)
A19: Sophia Myers | D19: =IF(OR(B19="",C19=""),"",C19-B19)
A20: Gracie North | D20: =IF(OR(B20="",C20=""),"",C20-B20)
A21: Kera Owenby | D21: =IF(OR(B21="",C21=""),"",C21-B21)
A22: Emmett Rhodarmer | D22: =IF(OR(B22="",C22=""),"",C22-B22)
A23: Leslie Rittenberry | D23: =IF(OR(B23="",C23=""),"",C23-B23)
A24: Teagan Rubianes | D24: =IF(OR(B24="",C24=""),"",C24-B24)
A25: Nolen Smallwood | D25: =IF(OR(B25="",C25=""),"",C25-B25)
A26: Stella Stewart | D26: =IF(OR(B26="",C26=""),"",C26-B26)
A27: Kaylee Thomas | D27: =IF(OR(B27="",C27=""),"",C27-B27)
... A64: Aubree Younglove | D64: =IF(OR(B64="",C64=""),"",C64-B64)
